### 一、try...catch

要使得 `try..catch` 能工作，代码必须是可执行的。换句话说，它必须是有效的 JavaScript 代码。

如果代码包含语法错误，那么 `try..catch` 将无法正常工作，例如含有不匹配的花括号：

```javascript
try {
  {{{{{{{{{{{{
} catch(e) {
  alert("The engine can't understand this code, it's invalid");
}
```

#### 1.1 错误对象

发生错误时，JavaScript 生成一个包含有关其详细信息的对象。然后将该对象作为参数传递给 `catch`：

```javascript
try {
  undefined()
} catch(err) { // <-- “error 对象”，也可以用其他参数名代替 err
  console.log(err.name)
  console.log(err.message)
  console.log(err.stack)
}
```

对于所有内建的 error，error 对象具有两个主要属性：

- `name`

  Error 名称。例如，对于一个未定义的变量，名称是 `"ReferenceError"`。

- `message`

  关于 error 的详细文字描述。

还有其他非标准的属性在大多数环境中可用。其中被最广泛使用和支持的是：

- `stack`

  当前的调用栈：用于调试目的的一个字符串，其中包含有关导致 error 的嵌套调用序列的信息

`catch`的参数具有块级作用域：

```javascript
try {
    undefined()
} catch(err) {
    console.log(err)
}
console.log(err) //无法访问
```

如果我们不需要 error 的详细信息，`catch` 也可以忽略它：

```javascript
try {
    ...
} catch {
    
}
```

#### 1.2 自定义Error

有时`try`代码块中没有语法错误，但由于诸如后台返回的数据对象缺少所需要的数据等情况，仍然需要抛出错误，这时就需要`throw`操作符抛出自定义错误：

```javascript
throw <error object>
```

从技术上讲，可以将任何东西用作 error 对象。甚至可以是一个原始类型数据，例如数字或字符串，但最好使用对象，最好使用具有 `name` 和 `message` 属性的对象（某种程度上保持与内建 error 的兼容性）。

JavaScript 中有很多内建的标准 error 的构造器：`Error`，`SyntaxError`，`ReferenceError`，`TypeError` 等。可以使用它们来创建 error 对象。它们的语法是：

```javascript
let error = new Error(message);
let error = new SyntaxError(message);
let error = new ReferenceError(message);
// ...
```

对于内建的 error（不是对于其他任何对象，仅仅是对于 error），`name` 属性刚好就是构造器的名字。`message` 则来自于参数（argument）。

**再次抛出**

实际上，catch 会捕获到 **所有** 来自于 `try` 的 error。如果`try`中的代码抛出了一个意料之外的错误，而catch中不知道如何应付这种错误。此时可以采用“重新抛出”技术。规则很简单：

**`catch` 应该只处理它知道的 error，并“抛出”所有其他 error。**“再次抛出（rethrowing）”技术可以被更详细地解释为：

1. `catch` 捕获所有 error。
2. 在 `catch(err) {...}` 块中，我们对 error 对象 `err` 进行分析。
3. 如果我们不知道如何处理它，那我们就 `throw err`。

通常，我们可以使用 `instanceof` 操作符判断错误类型：

```javascript
try {
  user = { /*...*/ };
} catch(err) {
  if (err instanceof ReferenceError) {
    alert('ReferenceError'); // 访问一个未定义（undefined）的变量产生了 "ReferenceError"
  }
}
```

除此之外还可以从 `err.name` 属性中获取错误的类名。所有原生的错误都有这个属性。另一种方式是读取 `err.constructor.name`。

#### 1.3 try...catch...finally

`try..catch` 结构可能还有一个代码子句（clause）：`finally`。如果它存在，它在所有情况下都会被执行。

在`try...catch...finally`中，`catch`是可选的，可以使用`try...finally`语句

#### 1.4 全局error

在 `try..catch` 结构外有一个致命的 error，然后脚本死亡了。此时我们有可能想要记录这个 error，并向用户显示某些内容（通常用户看不到错误信息）等。在规范中没有相关内容，但是代码的执行环境一般会提供这种机制。例如，Node.JS 有`process.on("uncaughtException")`。在浏览器中，我们可以将将一个函数赋值给特殊的 [window.onerror](https://developer.mozilla.org/zh/docs/Web/API/GlobalEventHandlers/onerror) 属性，该函数将在发生未捕获的 error 时执行。如：

```javascript
window.onerror = function(message, url, line, col, error) {
  // ...
};
```

- `message`

  Error 信息。

- `url`

  发生 error 的脚本的 URL。

- `line`，`col`

  发生 error 处的代码的行号和列号。

- `error`

  Error 对象。

全局错误处理程序 `window.onerror` 的作用通常不是恢复脚本的执行 — 如果发生编程错误，那这几乎是不可能的，它的作用是将错误信息发送给开发者。